Workbook
Name ListaProductosNuevos: 'Inventario ACTUAL (nuevo)'!$H$2:$H$90

Sheet LÉAME
A1: Qué es este archivo
B2: Lista de los 121 productos del inventario ANTERIOR de Motos (el que se borró el 30/09/2026, ya respaldado) para emparejarlos a mano con los 89 productos del inventario NUEVO actual.
A4: Hoja EMPAREJAR (la principal)
B5: Están los 121 productos anteriores, todos por igual, sin excepción. Primero va el producto ANTERIOR (columnas A-B, el que no tenía código de barras), y luego la sugerencia del producto NUEVO que sí tiene código (columnas C-E).
B6: Columnas C y D ("Producto nuevo sugerido" / "Código nuevo sugerido") se llenan solas con fórmula: si el nombre coincide EXACTO con uno del inventario nuevo, usa ese; si el parecido por texto supera el 70%, usa esa sugerencia; si no llega a ese nivel de confianza, quedan en blanco a propósito — es mejor no sugerir nada que sugerir algo probablemente equivocado. Columna E muestra el % de parecido como referencia, incluso cuando no hubo sugerencia (100% = coincidencia exacta).
B7: Columna F, "Código nuevo CONFIRMADO": ahí se elige, por cada fila, cuál es el producto del inventario NUEVO que realmente corresponde a ese producto anterior. Al hacer clic en la celda aparece una flechita con los 89 productos nuevos completos ("producto — código") para elegir buscando por nombre, sin tener que escribir el código a mano ni arriesgarse a poner uno que no exista.
B8: Columnas G y H ("Entradas histórico" / "Salidas histórico") son fórmulas SUMIFS que recalculan el total de entradas y salidas de cada producto a partir de la hoja "Movimientos ANTERIOR (detalle)", como control cruzado contra la columna I ("Stock al respaldo").
A10: Hoja "Movimientos ANTERIOR (detalle)"
B11: El histórico completo: cada entrada y cada salida del inventario anterior, una por fila, con fecha, cantidad, proveedor/N° de factura (en las entradas) o a quién se entregó/propósito (en las salidas), quién la registró, y el saldo que iba quedando después de cada movimiento. Use el filtro de la columna "Código" o "Producto" para ver el detalle de uno en particular. Entradas en verde, salidas en azul.
A13: Qué significa el color de las columnas C-E
B14: Verde: el nombre coincide exacto con uno del inventario nuevo (alta confianza).
B15: Amarillo: parecido muy alto (80% o más) — probablemente es, pero conviene confirmar.
B16: Naranja: parecido más moderado (71%-79%, el mínimo que se dejó en esta lista) — revisar con más cuidado, puede no ser el correcto.
A18: Filas con borde grueso
B19: Son los 4 productos de la última factura que quedó mal ingresada antes de borrar el inventario (N° 371, proveedor Colón Moto, 22/09/2026) — revisar esas con más cuidado.
A21: Otras hojas
B22: "Inventario ANTERIOR (borrado)": el listado completo tal como estaba antes de borrarlo, con sus códigos y cantidades de ese momento.
B23: "Inventario ACTUAL (nuevo)": el listado del inventario nuevo tal como está hoy en el sistema.

Sheet EMPAREJAR
A1: Código anterior | B1: Producto anterior (sin código de barras) | C1: Producto nuevo sugerido | D1: Código nuevo sugerido | E1: % de parecido (referencia) | F1: Código nuevo CONFIRMADO (clic y elegir de la lista) | G1: Entradas histórico (fórmula) | H1: Salidas histórico (fórmula) | I1: Stock al respaldo | J1: ¿De la última factura mal ingresada? | K1: Observaciones
A2: ='Inventario ANTERIOR (borrado)'!A2 | B2: ='Inventario ANTERIOR (borrado)'!B2 | C2: =IFERROR(INDEX('Inventario ACTUAL (nuevo)'!$B:$B,MATCH(B2,'Inventario ACTUAL (nuevo)'!$B:$B,0)),"") | D2: =IFERROR(INDEX('Inventario ACTUAL (nuevo)'!$A:$A,MATCH(B2,'Inventario ACTUAL (nuevo)'!$B:$B,0)),"") | E2: 40 | G2: =SUMIFS('Movimientos ANTERIOR (detalle)'!$E:$E,'Movimientos ANTERIOR (detalle)'!$A:$A,A2,'Movimientos ANTERIOR (detalle)'!$D:$D,"Entrada") | H2: =SUMIFS('Movimientos ANTERIOR (detalle)'!$E:$E,'Movimientos ANTERIOR (detalle)'!$A:$A,A2,'Movimientos ANTERIOR (detalle)'!$D:$D,"Salida") | I2: ='Inventario ANTERIOR (borrado)'!G2
A3: ='Inventario ANTERIOR (borrado)'!A3 | B3: ='Inventario ANTERIOR (borrado)'!B3 | C3: =IFERROR(INDEX('Inventario ACTUAL (nuevo)'!$B:$B,MATCH(B3,'Inventario ACTUAL (nuevo)'!$B:$B,0)),"") | D3: =IFERROR(INDEX('Inventario ACTUAL (nuevo)'!$A:$A,MATCH(B3,'Inventario ACTUAL (nuevo)'!$B:$B,0)),"") | E3: 62 | G3: =SUMIFS('Movimientos ANTERIOR (detalle)'!$E:$E,'Movimientos ANTERIOR (detalle)'!$A:$A,A3,'Movimientos ANTERIOR (detalle)'!$D:$D,"Entrada") | H3: =SUMIFS('Movimientos ANTERIOR (detalle)'!$E:$E,'Movimientos ANTERIOR (detalle)'!$A:$A,A3,'Movimientos ANTERIOR (detalle)'!$D:$D,"Salida") | I3: ='Inventario ANTERIOR (borrado)'!G3
A4: ='Inventario ANTERIOR (borrado)'!A4 | B4: ='Inventario ANTERIOR (borrado)'!B4 | C4: =IFERROR(INDEX('Inventario ACTUAL (nuevo)'!$B:$B,MATCH(B4,'Inventario ACTUAL (nuevo)'!$B:$B,0)),"") | D4: =IFERROR(INDEX('Inventario ACTUAL (nuevo)'!$A:$A,MATCH(B4,'Inventario ACTUAL (nuevo)'!$B:$B,0)),"") | E4: 69 | G4: =SUMIFS('Movimientos ANTERIOR (detalle)'!$E:$E,'Movimientos ANTERIOR (detalle)'!$A:$A,A4,'Movimientos ANTERIOR (detalle)'!$D:$D,"Entrada") | H4: =SUMIFS('Movimientos ANTERIOR (detalle)'!$E:$E,'Movimientos ANTERIOR (detalle)'!$A:$A,A4,'Movimientos ANTERIOR (detalle)'!$D:$D,"Salida") | I4: ='Inventario ANTERIOR (borrado)'!G4
A5: ='Inventario ANTERIOR (borrado)'!A5 | B5: ='Inventario ANTERIOR (borrado)'!B5 | C5: =IFERROR(INDEX('Inventario ACTUAL (nuevo)'!$B:$B,MATCH(B5,'Inventario ACTUAL (nuevo)'!$B:$B,0)),"Eje DELANTERO") | D5: =IFERROR(INDEX('Inventario ACTUAL (nuevo)'!$A:$A,MATCH(B5,'Inventario ACTUAL (nuevo)'!$B:$B,0)),"INTMUWUAG0EKQ") | E5: 77 | G5: =SUMIFS('Movimientos ANTERIOR (detalle)'!$E:$E,'Movimientos ANTERIOR (detalle)'!$A:$A,A5,'Movimientos ANTERIOR (detalle)'!$D:$D,"Entrada") | H5: =SUMIFS('Movimientos ANTERIOR (detalle)'!$E:$E,'Movimientos ANTERIOR (detalle)'!$A:$A,A5,'Movimientos ANTERIOR (detalle)'!$D:$D,"Salida") | I5: ='Inventario ANTERIOR (borrado)'!G5
A6: ='Inventario ANTERIOR (borrado)'!A6 | B6: ='Inventario ANTERIOR (borrado)'!B6 | C6: =IFERROR(INDEX('Inventario ACTUAL (nuevo)'!$B:$B,MATCH(B6,'Inventario ACTUAL (nuevo)'!$B:$B,0)),"") | D6: =IFERROR(INDEX('Inventario ACTUAL (nuevo)'!$A:$A,MATCH(B6,'Inventario ACTUAL (nuevo)'!$B:$B,0)),"") | E6: 45 | G6: =SUMIFS('Movimientos ANTERIOR (detalle)'!$E:$E,'Movimientos ANTERIOR (detalle)'!$A:$A,A6,'Movimientos ANTERIOR (detalle)'!$D:$D,"Entrada") | H6: =SUMIFS('Movimientos ANTERIOR (detalle)'!$E:$E,'Movimientos ANTERIOR (detalle)'!$A:$A,A6,'Movimientos ANTERIOR (detalle)'!$D:$D,"Salida") | I6: ='Inventario ANTERIOR (borrado)'!G6
A7: ='Inventario ANTERIOR (borrado)'!A7 | B7: ='Inventario ANTERIOR (borrado)'!B7 | C7: =IFERROR(INDEX('Inventario ACTUAL (nuevo)'!$B:$B,MATCH(B7,'Inventario ACTUAL (nuevo)'!$B:$B,0)),"PISADERO TRASERA") | D7: =IFERROR(INDEX('Inventario ACTUAL (nuevo)'!$A:$A,MATCH(B7,'Inventario ACTUAL (nuevo)'!$B:$B,0)),"INTMUR85SOCQ4") | E7: 74 | G7: =SUMIFS('Movimientos ANTERIOR (detalle)'!$E:$E,'Movimientos ANTERIOR (detalle)'!$A:$A,A7,'Movimientos ANTERIOR (detalle)'!$D:$D,"Entrada") | H7: =SUMIFS('Movimientos ANTERIOR (detalle)'!$E:$E,'Movimientos ANTERIOR (detalle)'!$A:$A,A7,'Movimientos ANTERIOR (detalle)'!$D:$D,"Salida") | I7: ='Inventario ANTERIOR (borrado)'!G7
A8: ='Inventario ANTERIOR (borrado)'!A8 | B8: ='Inventario ANTERIOR (borrado)'!B8 | C8: =IFERROR(INDEX('Inventario ACTUAL (nuevo)'!$B:$B,MATCH(B8,'Inventario ACTUAL (nuevo)'!$B:$B,0)),"") | D8: =IFERROR(INDEX('Inventario ACTUAL (nuevo)'!$A:$A,MATCH(B8,'Inventario ACTUAL (nuevo)'!$B:$B,0)),"") | E8: 54 | G8: =SUMIFS('Movimientos ANTERIOR (detalle)'!$E:$E,'Movimientos ANTERIOR (detalle)'!$A:$A,A8,'Movimientos ANTERIOR (detalle)'!$D:$D,"Entrada") | H8: =SUMIFS('Movimientos ANTERIOR (detalle)'!$E:$E,'Movimientos ANTERIOR (detalle)'!$A:$A,A8,'Movimientos ANTERIOR (detalle)'!$D:$D,"Salida") | I8: ='Inventario ANTERIOR (borrado)'!G8
A9: ='Inventario ANTERIOR (borrado)'!A9 | B9: ='Inventario ANTERIOR (borrado)'!B9 | C9: =IFERROR(INDEX('Inventario ACTUAL (nuevo)'!$B:$B,MATCH(B9,'Inventario ACTUAL (nuevo)'!$B:$B,0)),"BARA TELESCÓPICA") | D9: =IFERROR(INDEX('Inventario ACTUAL (nuevo)'!$A:$A,MATCH(B9,'Inventario ACTUAL (nuevo)'!$B:$B,0)),"INTMUR838GUDV") | E9: 73 | G9: =SUMIFS('Movimientos ANTERIOR (detalle)'!$E:$E,'Movimientos ANTERIOR (detalle)'!$A:$A,A9,'Movimientos ANTERIOR (detalle)'!$D:$D,"Entrada") | H9: =SUMIFS('Movimientos ANTERIOR (detalle)'!$E:$E,'Movimientos ANTERIOR (detalle)'!$A:$A,A9,'Movimientos ANTERIOR (detalle)'!$D:$D,"Salida") | I9: ='Inventario ANTERIOR (borrado)'!G9
A10: ='Inventario ANTERIOR (borrado)'!A10 | B10: ='Inventario ANTERIOR (borrado)'!B10 | C10: =IFERROR(INDEX('Inventario ACTUAL (nuevo)'!$B:$B,MATCH(B10,'Inventario ACTUAL (nuevo)'!$B:$B,0)),"BATERIA") | D10: =IFERROR(INDEX('Inventario ACTUAL (nuevo)'!$A:$A,MATCH(B10,'Inventario ACTUAL (nuevo)'!$B:$B,0)),"INTMUR7METY7D") | E10: 100 | G10: =SUMIFS('Movimientos ANTERIOR (detalle)'!$E:$E,'Movimientos ANTERIOR (detalle)'!$A:$A,A10,'Movimientos ANTERIOR (detalle)'!$D:$D,"Entrada") | H10: =SUMIFS('Movimientos ANTERIOR (detalle)'!$E:$E,'Movimientos ANTERIOR (detalle)'!$A:$A,A10,'Movimientos ANTERIOR (detalle)'!$D:$D,"Salida") | I10: ='Inventario ANTERIOR (borrado)'!G10
A11: ='Inventario ANTERIOR (borrado)'!A11 | B11: ='Inventario ANTERIOR (borrado)'!B11 | C11: =IFERROR(INDEX('Inventario ACTUAL (nuevo)'!$B:$B,MATCH(B11,'Inventario ACTUAL (nuevo)'!$B:$B,0)),"BENDIX") | D11: =IFERROR(INDEX('Inventario ACTUAL (nuevo)'!$A:$A,MATCH(B11,'Inventario ACTUAL (nuevo)'!$B:$B,0)),"INTMUR6CGIKOQ") | E11: 100 | G11: =SUMIFS('Movimientos ANTERIOR (detalle)'!$E:$E,'Movimientos ANTERIOR (detalle)'!$A:$A,A11,'Movimientos ANTERIOR (detalle)'!$D:$D,"Entrada") | H11: =SUMIFS('Movimientos ANTERIOR (detalle)'!$E:$E,'Movimientos ANTERIOR (detalle)'!$A:$A,A11,'Movimientos ANTERIOR (detalle)'!$D:$D,"Salida") | I11: ='Inventario ANTERIOR (borrado)'!G11
A12: ='Inventario ANTERIOR (borrado)'!A12 | B12: ='Inventario ANTERIOR (borrado)'!B12 | C12: =IFERROR(INDEX('Inventario ACTUAL (nuevo)'!$B:$B,MATCH(B12,'Inventario ACTUAL (nuevo)'!$B:$B,0)),"") | D12: =IFERROR(INDEX('Inventario ACTUAL (nuevo)'!$A:$A,MATCH(B12,'Inventario ACTUAL (nuevo)'!$B:$B,0)),"") | E12: 58 | G12: =SUMIFS('Movimientos ANTERIOR (detalle)'!$E:$E,'Movimientos ANTERIOR (detalle)'!$A:$A,A12,'Movimientos ANTERIOR (detalle)'!$D:$D,"Entrada") | H12: =SUMIFS('Movimientos ANTERIOR (detalle)'!$E:$E,'Movimientos ANTERIOR (detalle)'!$A:$A,A12,'Movimientos ANTERIOR (detalle)'!$D:$D,"Salida") | I12: ='Inventario ANTERIOR (borrado)'!G12
A13: ='Inventario ANTERIOR (borrado)'!A13 | B13: ='Inventario ANTERIOR (borrado)'!B13 | C13: =IFERROR(INDEX('Inventario ACTUAL (nuevo)'!$B:$B,MATCH(B13,'Inventario ACTUAL (nuevo)'!$B:$B,0)),"BOBINA BUJIA") | D13: =IFERROR(INDEX('Inventario ACTUAL (nuevo)'!$A:$A,MATCH(B13,'Inventario ACTUAL (nuevo)'!$B:$B,0)),"INTMUR6ET2S6X") | E13: 89 | G13: =SUMIFS('Movimientos ANTERIOR (detalle)'!$E:$E,'Movimientos ANTERIOR (detalle)'!$A:$A,A13,'Movimientos ANTERIOR (detalle)'!$D:$D,"Entrada") | H13: =SUMIFS('Movimientos ANTERIOR (detalle)'!$E:$E,'Movimientos ANTERIOR (detalle)'!$A:$A,A13,'Movimientos ANTERIOR (detalle)'!$D:$D,"Salida") | I13: ='Inventario ANTERIOR (borrado)'!G13
A14: ='Inventario ANTERIOR (borrado)'!A14 | B14: ='Inventario ANTERIOR (borrado)'!B14 | C14: =IFERROR(INDEX('Inventario ACTUAL (nuevo)'!$B:$B,MATCH(B14,'Inventario ACTUAL (nuevo)'!$B:$B,0)),"BOBINA DE CAMPO") | D14: =IFERROR(INDEX('Inventario ACTUAL (nuevo)'!$A:$A,MATCH(B14,'Inventario ACTUAL (nuevo)'!$B:$B,0)),"INTMUR75GL041") | E14: 100 | G14: =SUMIFS('Movimientos ANTERIOR (detalle)'!$E:$E,'Movimientos ANTERIOR (detalle)'!$A:$A,A14,'Movimientos ANTERIOR (detalle)'!$D:$D,"Entrada") | H14: =SUMIFS('Movimientos ANTERIOR (detalle)'!$E:$E,'Movimientos ANTERIOR (detalle)'!$A:$A,A14,'Movimientos ANTERIOR (detalle)'!$D:$D,"Salida") | I14: ='Inventario ANTERIOR (borrado)'!G14
A15: ='Inventario ANTERIOR (borrado)'!A15 | B15: ='Inventario ANTERIOR (borrado)'!B15 | C15: =IFERROR(INDEX('Inventario ACTUAL (nuevo)'!$B:$B,MATCH(B15,'Inventario ACTUAL (nuevo)'!$B:$B,0)),"") | D15: =IFERROR(INDEX('Inventario ACTUAL (nuevo)'!$A:$A,MATCH(B15,'Inventario ACTUAL (nuevo)'!$B:$B,0)),"") | E15: 59 | G15: =SUMIFS('Movimientos ANTERIOR (detalle)'!$E:$E,'Movimientos ANTERIOR (detalle)'!$A:$A,A15,'Movimientos ANTERIOR (detalle)'!$D:$D,"Entrada") | H15: =SUMIFS('Movimientos ANTERIOR (detalle)'!$E:$E,'Movimientos ANTERIOR (detalle)'!$A:$A,A15,'Movimientos ANTERIOR (detalle)'!$D:$D,"Salida") | I15: ='Inventario ANTERIOR (borrado)'!G15
A16: ='Inventario ANTERIOR (borrado)'!A16 | B16: ='Inventario ANTERIOR (borrado)'!B16 | C16: =IFERROR(INDEX('Inventario ACTUAL (nuevo)'!$B:$B,MATCH(B16,'Inventario ACTUAL (nuevo)'!$B:$B,0)),"") | D16: =IFERROR(INDEX('Inventario ACTUAL (nuevo)'!$A:$A,MATCH(B16,'Inventario ACTUAL (nuevo)'!$B:$B,0)),"") | E16: 59 | G16: =SUMIFS('Movimientos ANTERIOR (detalle)'!$E:$E,'Movimientos ANTERIOR (detalle)'!$A:$A,A16,'Movimientos ANTERIOR (detalle)'!$D:$D,"Entrada") | H16: =SUMIFS('Movimientos ANTERIOR (detalle)'!$E:$E,'Movimientos ANTERIOR (detalle)'!$A:$A,A16,'Movimientos ANTERIOR (detalle)'!$D:$D,"Salida") | I16: ='Inventario ANTERIOR (borrado)'!G16
A17: ='Inventario ANTERIOR (borrado)'!A17 | B17: ='Inventario ANTERIOR (borrado)'!B17 | C17: =IFERROR(INDEX('Inventario ACTUAL (nuevo)'!$B:$B,MATCH(B17,'Inventario ACTUAL (nuevo)'!$B:$B,0)),"DISCO DE FRENO DELANTERO") | D17: =IFERROR(INDEX('Inventario ACTUAL (nuevo)'!$A:$A,MATCH(B17,'Inventario ACTUAL (nuevo)'!$B:$B,0)),"INTMUR7VI1W4M") | E17: 83 | G17: =SUMIFS('Movimientos ANTERIOR (detalle)'!$E:$E,'Movimientos ANTERIOR (detalle)'!$A:$A,A17,'Movimientos ANTERIOR (detalle)'!$D:$D,"Entrada") | H17: =SUMIFS('Movimientos ANTERIOR (detalle)'!$E:$E,'Movimientos ANTERIOR (detalle)'!$A:$A,A17,'Movimientos ANTERIOR (detalle)'!$D:$D,"Salida") | I17: ='Inventario ANTERIOR (borrado)'!G17
A18: ='Inventario ANTERIOR (borrado)'!A18 | B18: ='Inventario ANTERIOR (borrado)'!B18 | C18: =IFERROR(INDEX('Inventario ACTUAL (nuevo)'!$B:$B,MATCH(B18,'Inventario ACTUAL (nuevo)'!$B:$B,0)),"") | D18: =IFERROR(INDEX('Inventario ACTUAL (nuevo)'!$A:$A,MATCH(B18,'Inventario ACTUAL (nuevo)'!$B:$B,0)),"") | E18: 48 | G18: =SUMIFS('Movimientos ANTERIOR (detalle)'!$E:$E,'Movimientos ANTERIOR (detalle)'!$A:$A,A18,'Movimientos ANTERIOR (detalle)'!$D:$D,"Entrada") | H18: =SUMIFS('Movimientos ANTERIOR (detalle)'!$E:$E,'Movimientos ANTERIOR (detalle)'!$A:$A,A18,'Movimientos ANTERIOR (detalle)'!$D:$D,"Salida") | I18: ='Inventario ANTERIOR (borrado)'!G18
A19: ='Inventario ANTERIOR (borrado)'!A19 | B19: ='Inventario ANTERIOR (borrado)'!B19 | C19: =IFERROR(INDEX('Inventario ACTUAL (nuevo)'!$B:$B,MATCH(B19,'Inventario ACTUAL (nuevo)'!$B:$B,0)),"") | D19: =IFERROR(INDEX('Inventario ACTUAL (nuevo)'!$A:$A,MATCH(B19,'Inventario ACTUAL (nuevo)'!$B:$B,0)),"") | E19: 50 | G19: =SUMIFS('Movimientos ANTERIOR (detalle)'!$E:$E,'Movimientos ANTERIOR (detalle)'!$A:$A,A19,'Movimientos ANTERIOR (detalle)'!$D:$D,"Entrada") | H19: =SUMIFS('Movimientos ANTERIOR (detalle)'!$E:$E,'Movimientos ANTERIOR (detalle)'!$A:$A,A19,'Movimientos ANTERIOR (detalle)'!$D:$D,"Salida") | I19: ='Inventario ANTERIOR (borrado)'!G19
A20: ='Inventario ANTERIOR (borrado)'!A20 | B20: ='Inventario ANTERIOR (borrado)'!B20 | C20: =IFERROR(INDEX('Inventario ACTUAL (nuevo)'!$B:$B,MATCH(B20,'Inventario ACTUAL (nuevo)'!$B:$B,0)),"") | D20: =IFERROR(INDEX('Inventario ACTUAL (nuevo)'!$A:$A,MATCH(B20,'Inventario ACTUAL (nuevo)'!$B:$B,0)),"") | E20: 48 | G20: =SUMIFS('Movimientos ANTERIOR (detalle)'!$E:$E,'Movimientos ANTERIOR (detalle)'!$A:$A,A20,'Movimientos ANTERIOR (detalle)'!$D:$D,"Entrada") | H20: =SUMIFS('Movimientos ANTERIOR (detalle)'!$E:$E,'Movimientos ANTERIOR (detalle)'!$A:$A,A20,'Movimientos ANTERIOR (detalle)'!$D:$D,"Salida") | I20: ='Inventario ANTERIOR (borrado)'!G20
A21: ='Inventario ANTERIOR (borrado)'!A21 | B21: ='Inventario ANTERIOR (borrado)'!B21 | C21: =IFERROR(INDEX('Inventario ACTUAL (nuevo)'!$B:$B,MATCH(B21,'Inventario ACTUAL (nuevo)'!$B:$B,0)),"BUJIA") | D21: =IFERROR(INDEX('Inventario ACTUAL (nuevo)'!$A:$A,MATCH(B21,'Inventario ACTUAL (nuevo)'!$B:$B,0)),"INTMUR7P7ZXKT") | E21: 91 | G21: =SUMIFS('Movimientos ANTERIOR (detalle)'!$E:$E,'Movimientos ANTERIOR (detalle)'!$A:$A,A21,'Movimientos ANTERIOR (detalle)'!$D:$D,"Entrada") | H21: =SUMIFS('Movimientos ANTERIOR (detalle)'!$E:$E,'Movimientos ANTERIOR (detalle)'!$A:$A,A21,'Movimientos ANTERIOR (detalle)'!$D:$D,"Salida") | I21: ='Inventario ANTERIOR (borrado)'!G21
A22: ='Inventario ANTERIOR (borrado)'!A22 | B22: ='Inventario ANTERIOR (borrado)'!B22 | C22: =IFERROR(INDEX('Inventario ACTUAL (nuevo)'!$B:$B,MATCH(B22,'Inventario ACTUAL (nuevo)'!$B:$B,0)),"") | D22: =IFERROR(INDEX('Inventario ACTUAL (nuevo)'!$A:$A,MATCH(B22,'Inventario ACTUAL (nuevo)'!$B:$B,0)),"") | E22: 52 | G22: =SUMIFS('Movimientos ANTERIOR (detalle)'!$E:$E,'Movimientos ANTERIOR (detalle)'!$A:$A,A22,'Movimientos ANTERIOR (detalle)'!$D:$D,"Entrada") | H22: =SUMIFS('Movimientos ANTERIOR (detalle)'!$E:$E,'Movimientos ANTERIOR (detalle)'!$A:$A,A22,'Movimientos ANTERIOR (detalle)'!$D:$D,"Salida") | I22: ='Inventario ANTERIOR (borrado)'!G22
A23: ='Inventario ANTERIOR (borrado)'!A23 | B23: ='Inventario ANTERIOR (borrado)'!B23 | C23: =IFERROR(INDEX('Inventario ACTUAL (nuevo)'!$B:$B,MATCH(B23,'Inventario ACTUAL (nuevo)'!$B:$B,0)),"CABLE DE EMBRAGUE") | D23: =IFERROR(INDEX('Inventario ACTUAL (nuevo)'!$A:$A,MATCH(B23,'Inventario ACTUAL (nuevo)'!$B:$B,0)),"INTMUR83JIS0S") | E23: 100 | G23: =SUMIFS('Movimientos ANTERIOR (detalle)'!$E:$E,'Movimientos ANTERIOR (detalle)'!$A:$A,A23,'Movimientos ANTERIOR (detalle)'!$D:$D,"Entrada") | H23: =SUMIFS('Movimientos ANTERIOR (detalle)'!$E:$E,'Movimientos ANTERIOR (detalle)'!$A:$A,A23,'Movimientos ANTERIOR (detalle)'!$D:$D,"Salida") | I23: ='Inventario ANTERIOR (borrado)'!G23
A24: ='Inventario ANTERIOR (borrado)'!A24 | B24: ='Inventario ANTERIOR (borrado)'!B24 | C24: =IFERROR(INDEX('Inventario ACTUAL (nuevo)'!$B:$B,MATCH(B24,'Inventario ACTUAL (nuevo)'!$B:$B,0)),"CABLE DE EMBRAGUE") | D24: =IFERROR(INDEX('Inventario ACTUAL (nuevo)'!$A:$A,MATCH(B24,'Inventario ACTUAL (nuevo)'!$B:$B,0)),"INTMUR83JIS0S") | E24: 85 | G24: =SUMIFS('Movimientos ANTERIOR (detalle)'!$E:$E,'Movimientos ANTERIOR (detalle)'!$A:$A,A24,'Movimientos ANTERIOR (detalle)'!$D:$D,"Entrada") | H24: =SUMIFS('Movimientos ANTERIOR (detalle)'!$E:$E,'Movimientos ANTERIOR (detalle)'!$A:$A,A24,'Movimientos ANTERIOR (detalle)'!$D:$D,"Salida") | I24: ='Inventario ANTERIOR (borrado)'!G24
A25: ='Inventario ANTERIOR (borrado)'!A25 | B25: ='Inventario ANTERIOR (borrado)'!B25 | C25: =IFERROR(INDEX('Inventario ACTUAL (nuevo)'!$B:$B,MATCH(B25,'Inventario ACTUAL (nuevo)'!$B:$B,0)),"CABLE DE ACELERACION") | D25: =IFERROR(INDEX('Inventario ACTUAL (nuevo)'!$A:$A,MATCH(B25,'Inventario ACTUAL (nuevo)'!$B:$B,0)),"INTMV1KJQIMPK") | E25: 72 | G25: =SUMIFS('Movimientos ANTERIOR (detalle)'!$E:$E,'Movimientos ANTERIOR (detalle)'!$A:$A,A25,'Movimientos ANTERIOR (detalle)'!$D:$D,"Entrada") | H25: =SUMIFS('Movimientos ANTERIOR (detalle)'!$E:$E,'Movimientos ANTERIOR (detalle)'!$A:$A,A25,'Movimientos ANTERIOR (detalle)'!$D:$D,"Salida") | I25: ='Inventario ANTERIOR (borrado)'!G25
A26: ='Inventario ANTERIOR (borrado)'!A26 | B26: ='Inventario ANTERIOR (borrado)'!B26 | C26: =IFERROR(INDEX('Inventario ACTUAL (nuevo)'!$B:$B,MATCH(B26,'Inventario ACTUAL (nuevo)'!$B:$B,0)),"CABLE DE VELOCÍMETRO") | D26: =IFERROR(INDEX('Inventario ACTUAL (nuevo)'!$A:$A,MATCH(B26,'Inventario ACTUAL (nuevo)'!$B:$B,0)),"INTMUR81G5095") | E26: 79 | G26: =SUMIFS('Movimientos ANTERIOR (detalle)'!$E:$E,'Movimientos ANTERIOR (detalle)'!$A:$A,A26,'Movimientos ANTERIOR (detalle)'!$D:$D,"Entrada") | H26: =SUMIFS('Movimientos ANTERIOR (detalle)'!$E:$E,'Movimientos ANTERIOR (detalle)'!$A:$A,A26,'Movimientos ANTERIOR (detalle)'!$D:$D,"Salida") | I26: ='Inventario ANTERIOR (borrado)'!G26
A27: ='Inventario ANTERIOR (borrado)'!A27 | B27: ='Inventario ANTERIOR (borrado)'!B27 | C27: =IFERROR(INDEX('Inventario ACTUAL (nuevo)'!$B:$B,MATCH(B27,'Inventario ACTUAL (nuevo)'!$B:$B,0)),"") | D27: =IFERROR(INDEX('Inventario ACTUAL (nuevo)'!$A:$A,MATCH(B27,'Inventario ACTUAL (nuevo)'!$B:$B,0)),"") | E27: 54 | G27: =SUMIFS('Movimientos ANTERIOR (detalle)'!$E:$E,'Movimientos ANTERIOR (detalle)'!$A:$A,A27,'Movimientos ANTERIOR (detalle)'!$D:$D,"Entrada") | H27: =SUMIFS('Movimientos ANTERIOR (detalle)'!$E:$E,'Movimientos ANTERIOR (detalle)'!$A:$A,A27,'Movimientos ANTERIOR (detalle)'!$D:$D,"Salida") | I27: ='Inventario ANTERIOR (borrado)'!G27
A28: ='Inventario ANTERIOR (borrado)'!A28 | B28: ='Inventario ANTERIOR (borrado)'!B28 | C28: =IFERROR(INDEX('Inventario ACTUAL (nuevo)'!$B:$B,MATCH(B28,'Inventario ACTUAL (nuevo)'!$B:$B,0)),"") | D28: =IFERROR(INDEX('Inventario ACTUAL (nuevo)'!$A:$A,MATCH(B28,'Inventario ACTUAL (nuevo)'!$B:$B,0)),"") | E28: 55 | G28: =SUMIFS('Movimientos ANTERIOR (detalle)'!$E:$E,'Movimientos ANTERIOR (detalle)'!$A:$A,A28,'Movimientos ANTERIOR (detalle)'!$D:$D,"Entrada") | H28: =SUMIFS('Movimientos ANTERIOR (detalle)'!$E:$E,'Movimientos ANTERIOR (detalle)'!$A:$A,A28,'Movimientos ANTERIOR (detalle)'!$D:$D,"Salida") | I28: ='Inventario ANTERIOR (borrado)'!G28
A29: ='Inventario ANTERIOR (borrado)'!A29 | B29: ='Inventario ANTERIOR (borrado)'!B29 | C29: =IFERROR(INDEX('Inventario ACTUAL (nuevo)'!$B:$B,MATCH(B29,'Inventario ACTUAL (nuevo)'!$B:$B,0)),"") | D29: =IFERROR(INDEX('Inventario ACTUAL (nuevo)'!$A:$A,MATCH(B29,'Inventario ACTUAL (nuevo)'!$B:$B,0)),"") | E29: 65 | G29: =SUMIFS('Movimientos ANTERIOR (detalle)'!$E:$E,'Movimientos ANTERIOR (detalle)'!$A:$A,A29,'Movimientos ANTERIOR (detalle)'!$D:$D,"Entrada") | H29: =SUMIFS('Movimientos ANTERIOR (detalle)'!$E:$E,'Movimientos ANTERIOR (detalle)'!$A:$A,A29,'Movimientos ANTERIOR (detalle)'!$D:$D,"Salida") | I29: ='Inventario ANTERIOR (borrado)'!G29
A30: ='Inventario ANTERIOR (borrado)'!A30 | B30: ='Inventario ANTERIOR (borrado)'!B30 | C30: =IFERROR(INDEX('Inventario ACTUAL (nuevo)'!$B:$B,MATCH(B30,'Inventario ACTUAL (nuevo)'!$B:$B,0)),"CAJA DE CAMBIO") | D30: =IFERROR(INDEX('Inventario ACTUAL (nuevo)'!$A:$A,MATCH(B30,'Inventario ACTUAL (nuevo)'!$B:$B,0)),"INTMUR7USTJEU") | E30: 100 | G30: =SUMIFS('Movimientos ANTERIOR (detalle)'!$E:$E,'Movimientos ANTERIOR (detalle)'!$A:$A,A30,'Movimientos ANTERIOR (detalle)'!$D:$D,"Entrada") | H30: =SUMIFS('Movimientos ANTERIOR (detalle)'!$E:$E,'Movimientos ANTERIOR (detalle)'!$A:$A,A30,'Movimientos ANTERIOR (detalle)'!$D:$D,"Salida") | I30: ='Inventario ANTERIOR (borrado)'!G30
A31: ='Inventario ANTERIOR (borrado)'!A31 | B31: ='Inventario ANTERIOR (borrado)'!B31 | C31: =IFERROR(INDEX('Inventario ACTUAL (nuevo)'!$B:$B,MATCH(B31,'Inventario ACTUAL (nuevo)'!$B:$B,0)),"CABLE DE ACELERACION") | D31: =IFERROR(INDEX('Inventario ACTUAL (nuevo)'!$A:$A,MATCH(B31,'Inventario ACTUAL (nuevo)'!$B:$B,0)),"INTMV1KJQIMPK") | E31: 74 | G31: =SUMIFS('Movimientos ANTERIOR (detalle)'!$E:$E,'Movimientos ANTERIOR (detalle)'!$A:$A,A31,'Movimientos ANTERIOR (detalle)'!$D:$D,"Entrada") | H31: =SUMIFS('Movimientos ANTERIOR (detalle)'!$E:$E,'Movimientos ANTERIOR (detalle)'!$A:$A,A31,'Movimientos ANTERIOR (detalle)'!$D:$D,"Salida") | I31: ='Inventario ANTERIOR (borrado)'!G31
A32: ='Inventario ANTERIOR (borrado)'!A32 | B32: ='Inventario ANTERIOR (borrado)'!B32 | C32: =IFERROR(INDEX('Inventario ACTUAL (nuevo)'!$B:$B,MATCH(B32,'Inventario ACTUAL (nuevo)'!$B:$B,0)),"") | D32: =IFERROR(INDEX('Inventario ACTUAL (nuevo)'!$A:$A,MATCH(B32,'Inventario ACTUAL (nuevo)'!$B:$B,0)),"") | E32: 55 | G32: =SUMIFS('Movimientos ANTERIOR (detalle)'!$E:$E,'Movimientos ANTERIOR (detalle)'!$A:$A,A32,'Movimientos ANTERIOR (detalle)'!$D:$D,"Entrada") | H32: =SUMIFS('Movimientos ANTERIOR (detalle)'!$E:$E,'Movimientos ANTERIOR (detalle)'!$A:$A,A32,'Movimientos ANTERIOR (detalle)'!$D:$D,"Salida") | I32: ='Inventario ANTERIOR (borrado)'!G32
A33: ='Inventario ANTERIOR (borrado)'!A33 | B33: ='Inventario ANTERIOR (borrado)'!B33 | C33: =IFERROR(INDEX('Inventario ACTUAL (nuevo)'!$B:$B,MATCH(B33,'Inventario ACTUAL (nuevo)'!$B:$B,0)),"") | D33: =IFERROR(INDEX('Inventario ACTUAL (nuevo)'!$A:$A,MATCH(B33,'Inventario ACTUAL (nuevo)'!$B:$B,0)),"") | E33: 52 | G33: =SUMIFS('Movimientos ANTERIOR (detalle)'!$E:$E,'Movimientos ANTERIOR (detalle)'!$A:$A,A33,'Movimientos ANTERIOR (detalle)'!$D:$D,"Entrada") | H33: =SUMIFS('Movimientos ANTERIOR (detalle)'!$E:$E,'Movimientos ANTERIOR (detalle)'!$A:$A,A33,'Movimientos ANTERIOR (detalle)'!$D:$D,"Salida") | I33: ='Inventario ANTERIOR (borrado)'!G33
A34: ='Inventario ANTERIOR (borrado)'!A34 | B34: ='Inventario ANTERIOR (borrado)'!B34 | C34: =IFERROR(INDEX('Inventario ACTUAL (nuevo)'!$B:$B,MATCH(B34,'Inventario ACTUAL (nuevo)'!$B:$B,0)),"CAUCHO TANQUE GN125") | D34: =IFERROR(INDEX('Inventario ACTUAL (nuevo)'!$A:$A,MATCH(B34,'Inventario ACTUAL (nuevo)'!$B:$B,0)),"INTMUR7ZJPNWD") | E34: 84 | G34: =SUMIFS('Movimientos ANTERIOR (detalle)'!$E:$E,'Movimientos ANTERIOR (detalle)'!$A:$A,A34,'Movimientos ANTERIOR (detalle)'!$D:$D,"Entrada") | H34: =SUMIFS('Movimientos ANTERIOR (detalle)'!$E:$E,'Movimientos ANTERIOR (detalle)'!$A:$A,A34,'Movimientos ANTERIOR (detalle)'!$D:$D,"Salida") | I34: ='Inventario ANTERIOR (borrado)'!G34
A35: ='Inventario ANTERIOR (borrado)'!A35 | B35: ='Inventario ANTERIOR (borrado)'!B35 | C35: =IFERROR(INDEX('Inventario ACTUAL (nuevo)'!$B:$B,MATCH(B35,'Inventario ACTUAL (nuevo)'!$B:$B,0)),"CAUCHO DE VALVULA") | D35: =IFERROR(INDEX('Inventario ACTUAL (nuevo)'!$A:$A,MATCH(B35,'Inventario ACTUAL (nuevo)'!$B:$B,0)),"INTMUR7OI4SFT") | E35: 97 | G35: =SUMIFS('Movimientos ANTERIOR (detalle)'!$E:$E,'Movimientos ANTERIOR (detalle)'!$A:$A,A35,'Movimientos ANTERIOR (detalle)'!$D:$D,"Entrada") | H35: =SUMIFS('Movimientos ANTERIOR (detalle)'!$E:$E,'Movimientos ANTERIOR (detalle)'!$A:$A,A35,'Movimientos ANTERIOR (detalle)'!$D:$D,"Salida") | I35: ='Inventario ANTERIOR (borrado)'!G35
A36: ='Inventario ANTERIOR (borrado)'!A36 | B36: ='Inventario ANTERIOR (borrado)'!B36 | C36: =IFERROR(INDEX('Inventario ACTUAL (nuevo)'!$B:$B,MATCH(B36,'Inventario ACTUAL (nuevo)'!$B:$B,0)),"CDI") | D36: =IFERROR(INDEX('Inventario ACTUAL (nuevo)'!$A:$A,MATCH(B36,'Inventario ACTUAL (nuevo)'!$B:$B,0)),"INTMUR7PL65J9") | E36: 100 | G36: =SUMIFS('Movimientos ANTERIOR (detalle)'!$E:$E,'Movimientos ANTERIOR (detalle)'!$A:$A,A36,'Movimientos ANTERIOR (detalle)'!$D:$D,"Entrada") | H36: =SUMIFS('Movimientos ANTERIOR (detalle)'!$E:$E,'Movimientos ANTERIOR (detalle)'!$A:$A,A36,'Movimientos ANTERIOR (detalle)'!$D:$D,"Salida") | I36: ='Inventario ANTERIOR (borrado)'!G36
A37: ='Inventario ANTERIOR (borrado)'!A37 | B37: ='Inventario ANTERIOR (borrado)'!B37 | C37: =IFERROR(INDEX('Inventario ACTUAL (nuevo)'!$B:$B,MATCH(B37,'Inventario ACTUAL (nuevo)'!$B:$B,0)),"CILINDRO") | D37: =IFERROR(INDEX('Inventario ACTUAL (nuevo)'!$A:$A,MATCH(B37,'Inventario ACTUAL (nuevo)'!$B:$B,0)),"INTMUR7NPK0NF") | E37: 73 | G37: =SUMIFS('Movimientos ANTERIOR (detalle)'!$E:$E,'Movimientos ANTERIOR (detalle)'!$A:$A,A37,'Movimientos ANTERIOR (detalle)'!$D:$D,"Entrada") | H37: =SUMIFS('Movimientos ANTERIOR (detalle)'!$E:$E,'Movimientos ANTERIOR (detalle)'!$A:$A,A37,'Movimientos ANTERIOR (detalle)'!$D:$D,"Salida") | I37: ='Inventario ANTERIOR (borrado)'!G37
A38: ='Inventario ANTERIOR (borrado)'!A38 | B38: ='Inventario ANTERIOR (borrado)'!B38 | C38: =IFERROR(INDEX('Inventario ACTUAL (nuevo)'!$B:$B,MATCH(B38,'Inventario ACTUAL (nuevo)'!$B:$B,0)),"") | D38: =IFERROR(INDEX('Inventario ACTUAL (nuevo)'!$A:$A,MATCH(B38,'Inventario ACTUAL (nuevo)'!$B:$B,0)),"") | E38: 58 | G38: =SUMIFS('Movimientos ANTERIOR (detalle)'!$E:$E,'Movimientos ANTERIOR (detalle)'!$A:$A,A38,'Movimientos ANTERIOR (detalle)'!$D:$D,"Entrada") | H38: =SUMIFS('Movimientos ANTERIOR (detalle)'!$E:$E,'Movimientos ANTERIOR (detalle)'!$A:$A,A38,'Movimientos ANTERIOR (detalle)'!$D:$D,"Salida") | I38: ='Inventario ANTERIOR (borrado)'!G38
A39: ='Inventario ANTERIOR (borrado)'!A39 | B39: ='Inventario ANTERIOR (borrado)'!B39 | C39: =IFERROR(INDEX('Inventario ACTUAL (nuevo)'!$B:$B,MATCH(B39,'Inventario ACTUAL (nuevo)'!$B:$B,0)),"DISCO DE FRENO DELANTERO") | D39: =IFERROR(INDEX('Inventario ACTUAL (nuevo)'!$A:$A,MATCH(B39,'Inventario ACTUAL (nuevo)'!$B:$B,0)),"INTMUR7VI1W4M") | E39: 100 | G39: =SUMIFS('Movimientos ANTERIOR (detalle)'!$E:$E,'Movimientos ANTERIOR (detalle)'!$A:$A,A39,'Movimientos ANTERIOR (detalle)'!$D:$D,"Entrada") | H39: =SUMIFS('Movimientos ANTERIOR (detalle)'!$E:$E,'Movimientos ANTERIOR (detalle)'!$A:$A,A39,'Movimientos ANTERIOR (detalle)'!$D:$D,"Salida") | I39: ='Inventario ANTERIOR (borrado)'!G39
A40: ='Inventario ANTERIOR (borrado)'!A40 | B40: ='Inventario ANTERIOR (borrado)'!B40 | C40: =IFERROR(INDEX('Inventario ACTUAL (nuevo)'!$B:$B,MATCH(B40,'Inventario ACTUAL (nuevo)'!$B:$B,0)),"DOBLE PATA") | D40: =IFERROR(INDEX('Inventario ACTUAL (nuevo)'!$A:$A,MATCH(B40,'Inventario ACTUAL (nuevo)'!$B:$B,0)),"INTMUR73NHKYJ") | E40: 100 | G40: =SUMIFS('Movimientos ANTERIOR (detalle)'!$E:$E,'Movimientos ANTERIOR (detalle)'!$A:$A,A40,'Movimientos ANTERIOR (detalle)'!$D:$D,"Entrada") | H40: =SUMIFS('Movimientos ANTERIOR (detalle)'!$E:$E,'Movimientos ANTERIOR (detalle)'!$A:$A,A40,'Movimientos ANTERIOR (detalle)'!$D:$D,"Salida") | I40: ='Inventario ANTERIOR (borrado)'!G40
...

Sheet Inventario ANTERIOR (borrado)
A1: Código anterior | B1: Producto | C1: Categoría | D1: Ubicación | E1: Entradas totales | F1: Salidas totales | G1: Stock al respaldo
A2: 067 | B2: ACCESORIO BOTÓN PRENDE Y APAGA 2CABLE | C2: SUZUKI | E2: 70 | F2: 0 | G2: 70
A3: 068 | B3: AMORTIGUADOR GN125 POSTERIOR | C3: SUZUKI | E3: 29 | F3: 0 | G3: 29
A4: 041 | B4: ANILLO DE FUEGO | C4: SUZUKI | D4: DURAN | E4: 104 | F4: 5 | G4: 99
A5: 020 | B5: ARO DELANTERO | C5: SUZUKI | D5: DURAN | E5: 0 | F5: 0 | G5: 0
A6: 069 | B6: ARO POST GN 125 REFORZADO | C6: SUZUKI | E6: 15 | F6: 0 | G6: 15
A7: 021 | B7: ARO TRASERO | C7: SUZUKI | D7: DURAN | E7: 0 | F7: 0 | G7: 0
A8: 071 | B8: AUTOMÁTICO GN 125 SIN CABLE | C8: SUZUKI | E8: 35 | F8: 0 | G8: 35
A9: 073 | B9: BARRA TELESCÓPICA GN125 NOVA | C9: SUZUKI | E9: 27 | F9: 0 | G9: 27
A10: 076 | B10: BATERIA | C10: SUZUKI | E10: 29 | F10: 0 | G10: 29
A11: 074 | B11: BENDIX | C11: SUZUKI | E11: 30 | F11: 0 | G11: 30
A12: 075 | B12: BOBIN CENTRAL GN 125 | C12: SUZUKI | E12: 0 | F12: 0 | G12: 0
A13: 045 | B13: BOBINA DE BUJIA | C13: SUZUKI | D13: DURAN | E13: 25 | F13: 0 | G13: 25
A14: 031 | B14: BOBINA DE CAMPO | C14: SUZUKI | D14: DURAN | E14: 35 | F14: 2 | G14: 33
A15: 0075 | B15: BOCÍN CENTRAL GN125 | C15: SUZUKI | E15: 80 | F15: 0 | G15: 80
A16: 003 | B16: BOLLA DE TANQUE | C16: SUZUKI | D16: CASA DURAN | E16: 0 | F16: 0 | G16: 0
A17: 057 | B17: BOMBA DE FRENO DELANTERO | C17: SUZUKI | D17: DURAN | E17: 0 | F17: 0 | G17: 0
A18: 730143313377 | B18: borrar amd | E18: 3 | F18: 0 | G18: 3
A19: 813002010089 | B19: borrar pilas | E19: 5 | F19: 0 | G19: 5
A20: 6935364085476 | B20: borrar tplink | E20: 5 | F20: 0 | G20: 5
A21: 062 | B21: BUJIAS | C21: SUZUKI | D21: DURAN | E21: 100 | F21: 0 | G21: 100
A22: 082 | B22: CABEZOTE COMPLETO GN125 | C22: SUZUKI | E22: 13 | F22: 0 | G22: 13
A23: 038 | B23: CABLE DE EMBRAGUE | C23: SUZUKI | D23: DURAN | E23: 0 | F23: 0 | G23: 0
A24: 078 | B24: CABLE DE EMBRAGUE GN125 | C24: SUZUKI | E24: 122 | F24: 3 | G24: 119
A25: 036 | B25: CABLE DE REVOLUCION | C25: SUZUKI | D25: DURAN | E25: 0 | F25: 0 | G25: 0
A26: 037 | B26: CABLE DE VELOCIDAD | C26: SUZUKI | D26: DURAN | E26: 30 | F26: 0 | G26: 30
A27: 077 | B27: CACHIMBA SOLA CG125 | C27: SUZUKI | E27: 50 | F27: 2 | G27: 48
A28: 080 | B28: CADENA 428H-132L | C28: SUZUKI | E28: 73 | F28: 3 | G28: 70
A29: 046 | B29: CADENILLA DE MOTOR | C29: SUZUKI | D29: DURAN | E29: 30 | F29: 7 | G29: 23
A30: 042 | B30: CAJA DE CAMBIO | C30: SUZUKI | D30: DURAN | E30: 0 | F30: 0 | G30: 0
A31: 022 | B31: CAÑA DE ACELERADOR | C31: SUZUKI | D31: DURAN | E31: 0 | F31: 0 | G31: 0
A32: 017 | B32: CARTONES DE PARCHE | C32: SUZUKI | D32: DURAN | E32: 0 | F32: 0 | G32: 0
A33: 081 | B33: CATALINA ACERO PULIDO GN125 | C33: SUZUKI | E33: 73 | F33: 3 | G33: 70
A34: 070 | B34: CAUCHO DE TANQUE GN | C34: SUZUKI | E34: 50 | F34: 0 | G34: 50
A35: 079 | B35: CAUCHO DE VALVULAS | C35: SUZUKI | E35: 30 | F35: 5 | G35: 25
A36: 032 | B36: CDI | C36: SUZUKI | D36: DURAN | E36: 20 | F36: 0 | G36: 20
A37: 083 | B37: CILINDRO GN125 | C37: SUZUKI | E37: 13 | F37: 6 | G37: 7
A38: 072 | B38: CINTA AISLANTE | C38: SUZUKI | E38: 50 | F38: 2 | G38: 48
A39: 034 | B39: DISCO DE FRENO DELANTERO | C39: SUZUKI | D39: DURAN | E39: 20 | F39: 0 | G39: 20
A40: 065 | B40: DOBLE PATA | C40: SUZUKI | D40: DURAN | E40: 0 | F40: 0 | G40: 0
...

Sheet Inventario ACTUAL (nuevo)
A1: Código nuevo | B1: Producto | C1: Categoría | D1: Ubicación | E1: Entradas totales | F1: Salidas totales | G1: Stock actual | H1: Para elegir (producto — código)
A2: INTMUR8220Q8C | B2: AMORTIGUADORES | E2: 14 | F2: 2 | G2: 12 | H2: AMORTIGUADORES — INTMUR8220Q8C
A3: INTMUR8DE0Z74 | B3: ANILLO | E3: 115 | F3: 14 | G3: 101 | H3: ANILLO — INTMUR8DE0Z74
A4: INTMV1KMVXFR5 | B4: ARANDELAS | E4: 8 | F4: 0 | G4: 8 | H4: ARANDELAS — INTMV1KMVXFR5
A5: INTMV1KKDKP5W | B5: ARBOL DE LEVA | E5: 3 | F5: 0 | G5: 3 | H5: ARBOL DE LEVA — INTMV1KKDKP5W
A6: INTMUR86PL0CA | B6: ASIENTO | E6: 9 | F6: 0 | G6: 9 | H6: ASIENTO — INTMUR86PL0CA
A7: INTMUR7506ZJG | B7: AUTOMÁTICO | E7: 33 | F7: 5 | G7: 28 | H7: AUTOMÁTICO — INTMUR7506ZJG
A8: INTMUR838GUDV | B8: BARA TELESCÓPICA | E8: 15 | F8: 0 | G8: 15 | H8: BARA TELESCÓPICA — INTMUR838GUDV
A9: INTMUR7METY7D | B9: BATERIA | E9: 18 | F9: 0 | G9: 18 | H9: BATERIA — INTMUR7METY7D
A10: INTMUR6CGIKOQ | B10: BENDIX | E10: 32 | F10: 0 | G10: 32 | H10: BENDIX — INTMUR6CGIKOQ
A11: INTMUR6ET2S6X | B11: BOBINA BUJIA | E11: 34 | F11: 2 | G11: 32 | H11: BOBINA BUJIA — INTMUR6ET2S6X
A12: INTMV1KKSWT28 | B12: BOBINA COR | E12: 4 | F12: 0 | G12: 4 | H12: BOBINA COR — INTMV1KKSWT28
A13: INTMUR75GL041 | B13: BOBINA DE CAMPO | E13: 3 | F13: 2 | G13: 1 | H13: BOBINA DE CAMPO — INTMUR75GL041
... A90: PH06430-0023 | B90: zapata de Freno | E90: 4 | F90: 0 | G90: 4 | H90: zapata de Freno — PH06430-0023

Sheet Movimientos ANTERIOR (detalle)
A1: Código | B1: Producto | C1: Fecha | D1: Tipo | E1: Cantidad | F1: Proveedor / Entregado a | G1: N° Factura / Propósito | H1: Usuario | I1: Saldo después de este movimiento
A2: 067 | B2: ACCESORIO BOTÓN PRENDE Y APAGA 2CABLE | C2: 2026-09-19 | D2: Entrada | E2: 70 | G2: 371 | H2: Administrador del Sistema | I2: 70
A3: 068 | B3: AMORTIGUADOR GN125 POSTERIOR | C3: 2026-09-19 | D3: Entrada | E3: 29 | G3: 731 | H3: Administrador del Sistema | I3: 29
A4: 041 | B4: ANILLO DE FUEGO | C4: 2026-09-19 | D4: Entrada | E4: 104 | H4: Administrador del Sistema | I4: 104
A5: 041 | B5: ANILLO DE FUEGO | C5: 2026-09-26 | D5: Salida | E5: 5 | F5: Coordinador Bone | G5: Taura c | H5: Bodega Durán | I5: 99
A6: 069 | B6: ARO POST GN 125 REFORZADO | C6: 2026-09-19 | D6: Entrada | E6: 4 | H6: Administrador del Sistema | I6: 4
A7: 069 | B7: ARO POST GN 125 REFORZADO | C7: 2026-09-19 | D7: Entrada | E7: 8 | G7: 731 | H7: Administrador del Sistema | I7: 12
A8: 069 | B8: ARO POST GN 125 REFORZADO | C8: 2026-09-19 | D8: Entrada | E8: 3 | H8: Administrador del Sistema | I8: 15
A9: 071 | B9: AUTOMÁTICO GN 125 SIN CABLE | C9: 2026-09-19 | D9: Entrada | E9: 35 | G9: 371 | H9: Administrador del Sistema | I9: 35
A10: 073 | B10: BARRA TELESCÓPICA GN125 NOVA | C10: 2026-09-19 | D10: Entrada | E10: 4 | G10: 371 | H10: Administrador del Sistema | I10: 4
A11: 073 | B11: BARRA TELESCÓPICA GN125 NOVA | C11: 2026-09-19 | D11: Entrada | E11: 23 | H11: Administrador del Sistema | I11: 27
A12: 076 | B12: BATERIA | C12: 2026-09-19 | D12: Entrada | E12: 29 | G12: 731 | H12: Administrador del Sistema | I12: 29
A13: 074 | B13: BENDIX | C13: 2026-09-19 | D13: Entrada | E13: 30 | G13: 431 | H13: Administrador del Sistema | I13: 30
A14: 045 | B14: BOBINA DE BUJIA | C14: 2026-09-19 | D14: Entrada | E14: 25 | H14: Administrador del Sistema | I14: 25
A15: 031 | B15: BOBINA DE CAMPO | C15: 2026-09-19 | D15: Entrada | E15: 25 | G15: 731 | H15: Administrador del Sistema | I15: 25
A16: 031 | B16: BOBINA DE CAMPO | C16: 2026-09-19 | D16: Entrada | E16: 10 | H16: Administrador del Sistema | I16: 35
A17: 031 | B17: BOBINA DE CAMPO | C17: 2026-09-26 | D17: Salida | E17: 2 | F17: Coordinador Bone | G17: Taura c | H17: Bodega Durán | I17: 33
A18: 0075 | B18: BOCÍN CENTRAL GN125 | C18: 2026-09-19 | D18: Entrada | E18: 80 | G18: 371 | H18: Administrador del Sistema | I18: 80
A19: 730143313377 | B19: borrar amd | C19: 2026-09-29 | D19: Entrada | E19: 3 | F19: Conteo físico | H19: Administrador del Sistema | I19: 3
A20: 813002010089 | B20: borrar pilas | C20: 2026-09-30 | D20: Entrada | E20: 5 | F20: Conteo físico | H20: Administrador del Sistema | I20: 5
A21: 6935364085476 | B21: borrar tplink | C21: 2026-09-30 | D21: Entrada | E21: 5 | F21: Conteo físico | H21: Administrador del Sistema | I21: 5
A22: 062 | B22: BUJIAS | C22: 2026-09-19 | D22: Entrada | E22: 100 | G22: 371 | H22: Administrador del Sistema | I22: 100
A23: 082 | B23: CABEZOTE COMPLETO GN125 | C23: 2026-09-19 | D23: Entrada | E23: 13 | G23: 371 | H23: Administrador del Sistema | I23: 13
A24: 078 | B24: CABLE DE EMBRAGUE GN125 | C24: 2026-09-19 | D24: Salida | E24: 3 | F24: Coordinador Ronald Mayorga | G24: Mantenimientos de motos | H24: Administrador del Sistema | I24: -3
A25: 078 | B25: CABLE DE EMBRAGUE GN125 | C25: 2026-09-19 | D25: Entrada | E25: 100 | G25: 371 | H25: Administrador del Sistema | I25: 97
A26: 078 | B26: CABLE DE EMBRAGUE GN125 | C26: 2026-09-19 | D26: Entrada | E26: 22 | F26: bodeg | H26: Administrador del Sistema | I26: 119
A27: 037 | B27: CABLE DE VELOCIDAD | C27: 2026-09-19 | D27: Entrada | E27: 30 | H27: Administrador del Sistema | I27: 30
A28: 077 | B28: CACHIMBA SOLA CG125 | C28: 2026-09-19 | D28: Salida | E28: 2 | F28: Coordinador Ronald Mayorga | G28: Mantenimientos de motos | H28: Administrador del Sistema | I28: -2
A29: 077 | B29: CACHIMBA SOLA CG125 | C29: 2026-09-19 | D29: Entrada | E29: 50 | G29: 731 | H29: Administrador del Sistema | I29: 48
A30: 080 | B30: CADENA 428H-132L | C30: 2026-09-19 | D30: Salida | E30: 3 | F30: Coor Mayorga/Tecnico Toala | G30: Corvinero | H30: Administrador del Sistema | I30: -3
A31: 080 | B31: CADENA 428H-132L | C31: 2026-09-19 | D31: Entrada | E31: 73 | G31: 371 | H31: Administrador del Sistema | I31: 70
A32: 046 | B32: CADENILLA DE MOTOR | C32: 2026-09-19 | D32: Entrada | E32: 30 | H32: Administrador del Sistema | I32: 30
A33: 046 | B33: CADENILLA DE MOTOR | C33: 2026-09-19 | D33: Salida | E33: 5 | F33: Coordinador Ronald Mayorga | G33: Mantenimientos de motos | H33: Administrador del Sistema | I33: 25
A34: 046 | B34: CADENILLA DE MOTOR | C34: 2026-09-26 | D34: Salida | E34: 2 | F34: Coordinador Bone | G34: Taura c | H34: Bodega Durán | I34: 23
A35: 081 | B35: CATALINA ACERO PULIDO GN125 | C35: 2026-09-19 | D35: Salida | E35: 3 | F35: Coordinador Ronald Mayorga | G35: Mantenimientos de motos | H35: Administrador del Sistema | I35: -3
A36: 081 | B36: CATALINA ACERO PULIDO GN125 | C36: 2026-09-19 | D36: Entrada | E36: 73 | G36: 371 | H36: Administrador del Sistema | I36: 70
A37: 070 | B37: CAUCHO DE TANQUE GN | C37: 2026-09-19 | D37: Entrada | E37: 50 | G37: 731 | H37: Administrador del Sistema | I37: 50
A38: 079 | B38: CAUCHO DE VALVULAS | C38: 2026-09-19 | D38: Entrada | E38: 30 | G38: 431 | H38: Administrador del Sistema | I38: 30
A39: 079 | B39: CAUCHO DE VALVULAS | C39: 2026-09-26 | D39: Salida | E39: 5 | F39: Coordinador Bone | G39: Taura c | H39: Bodega Durán | I39: 25
A40: 032 | B40: CDI | C40: 2026-09-19 | D40: Entrada | E40: 20 | G40: 431 | H40: Administrador del Sistema | I40: 20
...
